<?xml version="1.0"?>
<robot name="balance"
       xmlns:xi="http://www.w3.org/2001/XInclude"
       xmlns:gazebo="http://playerstage.sourceforge.net/gazebo/xmlschema/#gz"
       xmlns:model="http://playerstage.sourceforge.net/gazebo/xmlschema/#model"
       xmlns:sensor="http://playerstage.sourceforge.net/gazebo/xmlschema/#sensor"
       xmlns:body="http://playerstage.sourceforge.net/gazebo/xmlschema/#body"
       xmlns:geom="http://playerstage.sourceforge.net/gazebo/xmlschema/#geom"
       xmlns:joint="http://playerstage.sourceforge.net/gazebo/xmlschema/#joint"
       xmlns:interface="http://playerstage.sourceforge.net/gazebo/xmlschema/#interface"
       xmlns:rendering="http://playerstage.sourceforge.net/gazebo/xmlschema/#rendering"
       xmlns:renderable="http://playerstage.sourceforge.net/gazebo/xmlschema/#renderable"
       xmlns:controller="http://playerstage.sourceforge.net/gazebo/xmlschema/#controller"
       xmlns:physics="http://playerstage.sourceforge.net/gazebo/xmlschema/#physics">

  <link name="balance_base">
    <inertial>
      <mass value="5" />
      <origin xyz="0 0 0" rpy="0 0 0"/>
      <inertia ixx="0.025" ixy="0"  ixz="0"
               iyy="0.025" iyz="0"
               izz="0.0025" />
    </inertial>
    <visual>
      <origin xyz="0.0 0.0 0.0" rpy="0 0 0" />
      <geometry>
        <box size="0.04 0.04 0.04"/>
      </geometry>
    </visual>
    <collision>
      <origin xyz="0.0 0.0 0.0" rpy="0 0.0 0.0" />
      <geometry>
         <box size="0.04 0.04 0.04"/>
      </geometry>
    </collision>
  </link>
  <gazebo reference="balance_base">
    <material>Gazebo/BumpyMetal</material>
    <mu1>500.0</mu1>
    <mu2>500.0</mu2>
    <kp>100000000.0</kp>
    <kd>1.0</kd>
    <selfCollide>true</selfCollide>
    <turnGravityOff>false</turnGravityOff>
    <dampingFactor>0.001</dampingFactor>
  </gazebo>

  <link name="balance_plate">
    <inertial>
      <origin rpy="0 0 0" xyz="0 0.0 0.0"/>
      <mass value="1"/>
      <inertia ixx="1.0" ixy="0.0" ixz="0.0" iyy="0.0" iyz="0.0" izz="0.0"/>
    </inertial>
    <visual>
      <origin rpy="0 0 0" xyz="0 0 0"/>
      <geometry name="wrist_visual">
        <box size="0.1 0.02 0.005"/>
      </geometry>
    </visual>
    <collision>
      <origin rpy="0 0 0" xyz="0 0 0"/>
      <geometry name="wrist_collision_geom">
        <box size="0.1 0.02 0.005"/>
      </geometry>
    </collision>
  </link>
 <gazebo reference="balance_plate">
    <material>Gazebo/BumpyMetal</material>
    <mu1>500.0</mu1>
    <mu2>500.0</mu2>
    <kp>100000000.0</kp>
    <kd>1.0</kd>
    <selfCollide>true</selfCollide>
    <turnGravityOff>false</turnGravityOff>
    <dampingFactor>0.001</dampingFactor>
  </gazebo>


 <joint name="balance_pivot" type="revolute" >
    <parent link="balance_base" />
    <origin xyz="0 0 0.025" rpy="0 0 0" />
    <child link="balance_plate" />
    <axis xyz="0 1 0"/>
    <limit effort="10" lower="-0.25" upper="0.25" velocity="1.0"/>
 </joint>
</robot>




